<?xml version="1.0" encoding="utf-8"?>
<!-- =================================================================================== -->
<!-- |    This document was autogenerated by xacro from situation.urdf.xacro           | -->
<!-- |    EDITING THIS FILE BY HAND IS NOT RECOMMENDED                                 | -->
<!-- =================================================================================== -->
<robot name="lwa4p">
  <material name="LightGrey">
    <color rgba="0.7 0.7 0.7 1.0"/>
  </material>
  <material name="DarkGrey">
    <color rgba="0.4 0.4 0.4 1.0"/>
  </material>
  <material name="Black">
    <color rgba="0.0 0.0 0.0 1.0"/>
  </material>
  <material name="DarkGolden">
    <color rgba="0.4 0.4 0.3 1.0"/>
  </material>
  <material name="Blue">
    <color rgba="0.0 0.0 0.8 1.0"/>
  </material>
  <!-- Used for fixing robot to Gazebo -->
  <link name="world"/>
  <!-- joint between base_link and lwa4p_extended_connector_link -->
  <joint name="arm_podest_joint" type="fixed">
    <origin rpy="0 0 0" xyz="0 0 0.052"/>
    <parent link="world"/>
    <child link="arm_podest_link"/>
  </joint>
  <link name="arm_podest_link">
    <inertial>
      <mass value="0.01"/>
      <origin xyz="0 0 0"/>
      <inertia ixx="0.001" ixy="0.0" ixz="0.0" iyy="0.001" iyz="0.0" izz="0.001"/>
    </inertial>
    <visual>
      <origin rpy="0 3.14159265359 0" xyz="0 0 0.75"/>
      <geometry>
        <!--mesh filename="package://model_description/meshes/arm_base_link.stl" /-->
        <mesh filename="meshes/arm_base_link.stl"/>
      </geometry>
    </visual>
    <collision>
      <origin rpy="0 3.14159265359 0" xyz="0 0 0.75"/>
      <geometry>
        <!--mesh filename="package://model_description/meshes/arm_base_link.stl" /-->
        <mesh filename="meshes/arm_base_link.stl"/>
      </geometry>
    </collision>
  </link>
  <joint name="arm_base_joint" type="fixed">
    <origin rpy="0 0 0" xyz="0 0 0.10"/>
    <parent link="arm_podest_link"/>
    <child link="arm_base_link"/>
  </joint>
  <link name="arm_base_link">
    <inertial>
      <mass value="0.01"/>
      <origin xyz="0 0 0"/>
      <inertia ixx="0.001" ixy="0.0" ixz="0.0" iyy="0.001" iyz="0.0" izz="0.001"/>
    </inertial>
  </link>
  <!-- joint between arm_0_link and arm_1_link -->
  <joint name="arm_1_joint" type="revolute">
    <origin rpy="0 0 3.14159265359" xyz="0 0 0.75"/>
    <parent link="arm_base_link"/>
    <child link="arm_1_link"/>
    <axis xyz="0 0 1"/>
    <limit effort="370" lower="-2.947" upper="2.947" velocity="1.26"/>
    <!--safety_controller k_position="20" k_velocity="50" soft_lower_limit="${-6.28 + 0.01}" soft_upper_limit="${6.28 - 0.01}" /-->
  </joint>
  <link name="arm_1_link">
    <inertial>
      <mass value="0.01"/>
      <origin xyz="0 0 0"/>
      <inertia ixx="0.001" ixy="0.0" ixz="0.0" iyy="0.001" iyz="0.0" izz="0.001"/>
    </inertial>
    <!--
      <inertial>
        <origin xyz="0 0 0" rpy="0 0 0" />
        <mass value="0.29364"/>
        <inertia ixx="0.01" ixy="0" ixz="0" iyy="0.01" iyz="0" izz="0.01" />
      </inertial>
-->
    <visual>
      <origin rpy="0 0 0" xyz="0 0 0"/>
      <geometry>
        <!--mesh filename="package://model_description/meshes/arm_1_link.stl" /-->
        <mesh filename="meshes/arm_1_link.stl"/>
      </geometry>
      <material name="Blue"/>
    </visual>
    <collision>
      <origin rpy="0 0 0" xyz="0 0 0"/>
      <geometry>
        <!--mesh filename="package://model_description/meshes/arm_1_link.stl" /-->
        <mesh filename="meshes/arm_1_link.stl"/>
      </geometry>
    </collision>
  </link>
  <!-- joint between arm_1_link and arm_2_link -->
  <joint name="arm_2_joint" type="revolute">
    <origin rpy="1.5708 0 0" xyz="0 0 0"/>
    <parent link="arm_1_link"/>
    <child link="arm_2_link"/>
    <axis xyz="0 0 1"/>
    <limit effort="370" lower="-2.947" upper="2.947" velocity="1.26"/>
    <!--safety_controller k_position="20" k_velocity="50" soft_lower_limit="${-2.09 + 0.01}" soft_upper_limit="${2.09 - 0.01}" /-->
  </joint>
  <link name="arm_2_link">
    <inertial>
      <mass value="0.01"/>
      <origin xyz="0 0 0"/>
      <inertia ixx="0.001" ixy="0.0" ixz="0.0" iyy="0.001" iyz="0.0" izz="0.001"/>
    </inertial>
    <!--
      <inertial>
        <origin xyz="0 0 0" rpy="0 0 0"/>
        <mass value="1.68311"/>
        <inertia ixx="0.03" ixy="0" ixz="0" iyy="0.03" iyz="0" izz="0.03" />
      </inertial>
-->
    <visual>
      <origin rpy="0 0 0" xyz="0 0 0"/>
      <geometry>
        <!--mesh filename="package://model_description/meshes/arm_2_link.stl" /-->
        <mesh filename="meshes/arm_2_link.stl"/>
      </geometry>
      <material name="LightGrey"/>
    </visual>
    <collision>
      <origin rpy="0 0 0" xyz="0 0 0"/>
      <geometry>
        <!--mesh filename="package://model_description/meshes/arm_2_link.stl" /-->
        <mesh filename="meshes/arm_2_link.stl"/>
      </geometry>
    </collision>
  </link>
  <!-- joint between arm_2_link and arm_3_link -->
  <joint name="arm_3_joint" type="revolute">
    <origin rpy="0 3.14159 0" xyz="0 0.350 0"/>
    <parent link="arm_2_link"/>
    <child link="arm_3_link"/>
    <axis xyz="0 0 1"/>
    <limit effort="176" lower="-2.694" upper="2.694" velocity="1.26"/>
    <!--safety_controller k_position="20" k_velocity="25" soft_lower_limit="${-6.28 + 0.01}" soft_upper_limit="${6.28 - 0.01}" /-->
  </joint>
  <link name="arm_3_link">
    <inertial>
      <mass value="0.01"/>
      <origin xyz="0 0 0"/>
      <inertia ixx="0.001" ixy="0.0" ixz="0.0" iyy="0.001" iyz="0.0" izz="0.001"/>
    </inertial>
    <!--
      <inertial>
        <origin xyz="0 0 0" rpy="0 0 0"/>
        <mass value="2.1"/>
        <inertia ixx="0.03" ixy="0" ixz="0" iyy="0.03" iyz="0" izz="0.03" />
      </inertial>
-->
    <visual>
      <origin rpy="0 0 0" xyz="0 0 0"/>
      <geometry>
        <!--mesh filename="package://model_description/meshes/arm_3_link.stl" /-->
        <mesh filename="meshes/arm_3_link.stl"/>
      </geometry>
      <material name="Blue"/>
    </visual>
    <collision>
      <origin rpy="0 0 0" xyz="0 0 0"/>
      <geometry>
        <!--mesh filename="package://model_description/meshes/arm_3_link.stl" /-->
        <mesh filename="meshes/arm_3_link.stl"/>
      </geometry>
    </collision>
  </link>
  <!-- joint between arm_3_link and arm_4_link -->
  <joint name="arm_4_joint" type="revolute">
    <origin rpy="-1.5708 3.14159 0" xyz="0 0 0"/>
    <parent link="arm_3_link"/>
    <child link="arm_4_link"/>
    <axis xyz="0 0 1"/>
    <limit effort="176" lower="-2.947" upper="2.947" velocity="1.26"/>
    <!--safety_controller k_position="20" k_velocity="25" soft_lower_limit="${-2.09 + 0.01}" soft_upper_limit="${2.09 - 0.01}" /-->
  </joint>
  <link name="arm_4_link">
    <inertial>
      <mass value="0.01"/>
      <origin xyz="0 0 0"/>
      <inertia ixx="0.001" ixy="0.0" ixz="0.0" iyy="0.001" iyz="0.0" izz="0.001"/>
    </inertial>
    <!--
      <inertial>
        <origin xyz="0 0 0" rpy="0 0 0"/>
        <mass value="1.68311"/>
        <inertia ixx="0.03" ixy="0" ixz="0" iyy="0.03" iyz="0" izz="0.03" />
      </inertial>
-->
    <visual>
      <origin rpy="0 0 0" xyz="0 0 0"/>
      <geometry>
        <!--mesh filename="package://model_description/meshes/arm_4_link.stl" /-->
        <mesh filename="meshes/arm_4_link.stl"/>
      </geometry>
      <material name="LightGrey"/>
    </visual>
    <collision>
      <origin rpy="0 0 0" xyz="0 0 0"/>
      <geometry>
        <!--mesh filename="package://model_description/meshes/arm_4_link.stl" /-->
        <mesh filename="meshes/arm_4_link.stl"/>
      </geometry>
    </collision>
  </link>
  <!-- joint between arm_4_link and arm_5_link -->
  <joint name="arm_5_joint" type="revolute">
    <origin rpy="1.5708 0 3.14159" xyz="0 0.005263 0.305"/>
    <parent link="arm_4_link"/>
    <child link="arm_5_link"/>
    <axis xyz="0 0 1"/>
    <limit effort="41.6" lower="-2.947" upper="2.947" velocity="1.26"/>
    <!--safety_controller k_position="20" k_velocity="25" soft_lower_limit="${-6.28 + 0.01}" soft_upper_limit="${6.28 - 0.01}" /-->
  </joint>
  <link name="arm_5_link">
    <!--inertial>
      <mass value="0.01"/>
      <origin xyz="0 0 0"/>
      <inertia ixx="0.001" ixy="0.0" ixz="0.0" iyy="0.001" iyz="0.0" izz="0.001"/>
    </inertial-->
    
     <inertial>
      <mass value="0.29364"/>
      <inertia ixx="0.01" ixy="0" ixz="0" iyy="0.01" iyz="0" izz="0.01"/>
      <origin rpy="0 0 0" xyz="0 0 0"/>
    </inertial>

    <visual>
      <origin rpy="0 0 0" xyz="0 0 0"/>
      <geometry>
        <!--mesh filename="package://model_description/meshes/arm_5_link.stl" /-->
        <mesh filename="meshes/arm_5_link.stl"/>
      </geometry>
      <material name="Blue"/>
    </visual>
    <collision>
      <origin rpy="0 0 0" xyz="0 0 0"/>
      <geometry>
        <!--mesh filename="package://model_description/meshes/arm_5_link.stl" /-->
        <mesh filename="meshes/arm_5_link.stl"/>
      </geometry>
    </collision>
  </link>
  <!-- joint between arm_5_link and arm_6_link -->
  <joint name="arm_6_joint" type="revolute">
    <origin rpy="-1.5708 0 0" xyz="0 0 0"/>
    <parent link="arm_5_link"/>
    <child link="arm_6_link"/>
    <axis xyz="0 0 1"/>
    <limit effort="20.1" lower="-2.947" upper="2.947" velocity="1.26"/>
    <!--safety_controller k_position="20" k_velocity="25" soft_lower_limit="${-2.09 + 0.01}" soft_upper_limit="${2.09 - 0.01}" /-->
  </joint>
  <link name="arm_6_link">
    <inertial>
      <mass value="0.01"/>
      <origin xyz="0 0 0"/>
      <inertia ixx="0.001" ixy="0.0" ixz="0.0" iyy="0.001" iyz="0.0" izz="0.001"/>
    </inertial>
    <!--
      <inertial>
        <origin xyz="0 0 0" rpy="0 0 0"/>
        <mass value="0.819"/>
        <inertia ixx="0.01" ixy="0" ixz="0" iyy="0.01" iyz="0" izz="0.01" />
      </inertial>
-->
    <visual>
      <origin rpy="0 0 0" xyz="0 0 0"/>
      <geometry>
        <!--mesh filename="package://model_description/meshes/arm_6_link.stl" /-->
        <mesh filename="meshes/arm_6_link.stl"/>
      </geometry>
      <material name="LightGrey"/>
    </visual>
    <collision>
      <origin rpy="0 0 0" xyz="0 0 0"/>
      <geometry>
        <!--mesh filename="package://model_description/meshes/lwa4p/arm_6_link.stl" /-->
        <mesh filename="meshes/arm_6_link.stl"/>
      </geometry>
    </collision>
  </link>
  <gazebo reference="arm_base_link">
    <gravity>true</gravity>
    <mu1>0.0</mu1>
    <mu2>0.0</mu2>
    <self_collide>false</self_collide>
    <material>Gazebo/LightGrey</material>
  </gazebo>
  <gazebo reference="arm_1_link">
    <gravity>true</gravity>
    <mu1>0.0</mu1>
    <mu2>0.0</mu2>
    <self_collide>false</self_collide>
    <material>Gazebo/Blue</material>
  </gazebo>
  <gazebo reference="arm_2_link">
    <gravity>true</gravity>
    <mu1>0.0</mu1>
    <mu2>0.0</mu2>
    <self_collide>false</self_collide>
    <material>Gazebo/LightGrey</material>
  </gazebo>
  <gazebo reference="arm_3_link">
    <gravity>true</gravity>
    <mu1>0.0</mu1>
    <mu2>0.0</mu2>
    <self_collide>false</self_collide>
    <material>Gazebo/Black</material>
  </gazebo>
  <gazebo reference="arm_4_link">
    <gravity>true</gravity>
    <mu1>0.0</mu1>
    <mu2>0.0</mu2>
    <self_collide>false</self_collide>
    <material>Gazebo/LightGrey</material>
  </gazebo>
  <gazebo reference="arm_5_link">
    <gravity>true</gravity>
    <mu1>0.0</mu1>
    <mu2>0.0</mu2>
    <self_collide>false</self_collide>
    <material>Gazebo/Black</material>
  </gazebo>
  <gazebo reference="arm_6_link">
    <gravity>true</gravity>
    <mu1>0.0</mu1>
    <mu2>0.0</mu2>
    <self_collide>false</self_collide>
    <material>Gazebo/LightGrey</material>
  </gazebo>
  <gazebo reference="arm_7_link">
    <gravity>true</gravity>
    <mu1>0.0</mu1>
    <mu2>0.0</mu2>
    <self_collide>false</self_collide>
    <material>Gazebo/Black</material>
  </gazebo>
  <!--xacro:schunk_lwa4p_transmission name="${name}" /-->
  <!-- ros_control plugin -->
  <!--gazebo-->
  <!--plugin name="gazebo_ros_control" filename="libgazebo_ros_control.so">
        <robotNamespace>${name}</robotNamespace>
        <filterJointsParam>joint_names</filterJointsParam>
        <legacyModeNS>true</legacyModeNS>
      </plugin-->
  <!--plugin name="my_joint_plugin" filename="libJoints.so">
        <joint_topic>/traj_info</joint_topic>
        <joint_names>joint_names</joint_names>
        <default_value>q0</default_value>
      </plugin>
    </gazebo-->
  <!-- sensors -->
  <!--xacro:property name="sensors_data" value="${load_yaml('$(find human_cylinder)/config/sensors_parameters.yaml')}"/-->
  <!-- light curtains -->
  <!--xacro:macro name="curtains_loop" params="N">
    <xacro:property name="curtain" value="'curtain_${N}'"/>
    <xacro:light_curtains id="${sensors_data[curtain]['id']}" x1="${sensors_data[curtain]['pos'][0]}" y1="${sensors_data[curtain]['pos'][1]}" x2="${sensors_data[curtain]['pos'][2]}" y2="${sensors_data[curtain]['pos'][3]}" parent="world"/>
    <xacro:if value="${N}">
      <xacro:curtains_loop N="${N-1}" />
    </xacro:if>
  </xacro:macro>

  <xacro:if value="${sensors_data['nb_curtains']}">
    <xacro:curtains_loop N="${sensors_data['nb_curtains']-1}"/>
  </xacro:if-->
  <!-- presence sensor -->
  <!--xacro:if value="${sensors_data['nb_presence_sensors']}">
    <xacro:presence_sensors parent="world"/>
  </xacro:if-->
  <!-- laser_scanners -->
  <!--xacro:macro name="scanners_loop" params="N">
    <xacro:property name="scanner" value="'laser_scanner_${N}'"/>
    <xacro:laser_scanners id="${sensors_data[scanner]['id']}" x="${sensors_data[scanner]['origin'][0]}" y="${sensors_data[scanner]['origin'][1]}" theta="${sensors_data[scanner]['origin'][2]}" range="${sensors_data[scanner]['range']}" parent="world"/>
    <xacro:if value="${N}">
      <xacro:scanners_loop N="${N-1}" />
    </xacro:if>
  </xacro:macro-->
  <!--xacro:if value="${sensors_data['nb_laser_scanners']}">
    <xacro:scanners_loop N="${sensors_data['nb_laser_scanners']-1}"/>
  </xacro:if-->
</robot>

